Workbook

Sheet 안내
A1: 초등 성취기준 학년별 배치표 (2022 개정 교육과정 · 2026학년도)
A3: 자료
A4: 성취기준: 초등_성취기준_학년군별.xlsx (suseok-exam / prep-materials, 교육부 고시 제2022-33호) 중 9개 교과 523개
A5: 단원: 2026학년도 학교 연간 지도 계획(1~6학년 1·2학기, hwp 89개)
A7: 배치 방법
A8: 성취기준 문장과 계획서의 단원·차시 내용을 대조해 학년·학기·단원을 정하고, 어긋난 항목은 직접 검토해 바로잡았습니다(근거 열).
A9: 자동 대조: 문장 유사도로 배치 / 검토 보정: 교사 검토로 수정 / 영역 대단원: 체육은 영역(운동·스포츠·표현) 대단원에 배치
A11: 구분
A12: 단일 학년: 한 학년에서만 다룸
A13: 두 학년 공통: 같은 학년군의 두 학년에서 모두 다룸 (노란 칸)
A14: 두 학년 반복·심화: 음악·미술·체육처럼 두 학년에 걸쳐 반복·심화하는 교과 (연녹색 칸)
A16: 빠진 자료
... A23: 학년별 성취기준 수 (각 학년 시트에서 자동 집계)
A24: 교과 | B24: 1학년 | C24: 2학년 | D24: 3학년 | E24: 4학년 | F24: 5학년 | G24: 6학년 | H24: 합계
A25: 국어 | B25: =COUNTIF(1학년!$A:$A,$A25) -> 8 | C25: =COUNTIF(2학년!$A:$A,$A25) -> 18 | D25: =COUNTIF(3학년!$A:$A,$A25) -> 17 | E25: =COUNTIF(4학년!$A:$A,$A25) -> 17 | F25: =COUNTIF(5학년!$A:$A,$A25) -> 18 | G25: =COUNTIF(6학년!$A:$A,$A25) -> 20 | H25: =SUM(B25:G25) -> 98
A26: 수학 | B26: =COUNTIF(1학년!$A:$A,$A26) -> 13 | C26: =COUNTIF(2학년!$A:$A,$A26) -> 22 | D26: =COUNTIF(3학년!$A:$A,$A26) -> 25 | E26: =COUNTIF(4학년!$A:$A,$A26) -> 26 | F26: =COUNTIF(5학년!$A:$A,$A26) -> 24 | G26: =COUNTIF(6학년!$A:$A,$A26) -> 22 | H26: =SUM(B26:G26) -> 132
A27: 사회 | B27: =COUNTIF(1학년!$A:$A,$A27) -> 0 | C27: =COUNTIF(2학년!$A:$A,$A27) -> 0 | D27: =COUNTIF(3학년!$A:$A,$A27) -> 10 | E27: =COUNTIF(4학년!$A:$A,$A27) -> 12 | F27: =COUNTIF(5학년!$A:$A,$A27) -> 13 | G27: =COUNTIF(6학년!$A:$A,$A27) -> 15 | H27: =SUM(B27:G27) -> 50
A28: 과학 | B28: =COUNTIF(1학년!$A:$A,$A28) -> 0 | C28: =COUNTIF(2학년!$A:$A,$A28) -> 0 | D28: =COUNTIF(3학년!$A:$A,$A28) -> 25 | E28: =COUNTIF(4학년!$A:$A,$A28) -> 26 | F28: =COUNTIF(5학년!$A:$A,$A28) -> 25 | G28: =COUNTIF(6학년!$A:$A,$A28) -> 27 | H28: =SUM(B28:G28) -> 103
A29: 도덕 | B29: =COUNTIF(1학년!$A:$A,$A29) -> 0 | C29: =COUNTIF(2학년!$A:$A,$A29) -> 0 | D29: =COUNTIF(3학년!$A:$A,$A29) -> 6 | E29: =COUNTIF(4학년!$A:$A,$A29) -> 7 | F29: =COUNTIF(5학년!$A:$A,$A29) -> 6 | G29: =COUNTIF(6학년!$A:$A,$A29) -> 6 | H29: =SUM(B29:G29) -> 25
A30: 실과 | B30: =COUNTIF(1학년!$A:$A,$A30) -> 0 | C30: =COUNTIF(2학년!$A:$A,$A30) -> 0 | D30: =COUNTIF(3학년!$A:$A,$A30) -> 0 | E30: =COUNTIF(4학년!$A:$A,$A30) -> 0 | F30: =COUNTIF(5학년!$A:$A,$A30) -> 22 | G30: =COUNTIF(6학년!$A:$A,$A30) -> 18 | H30: =SUM(B30:G30) -> 40
A31: 체육 | B31: =COUNTIF(1학년!$A:$A,$A31) -> 0 | C31: =COUNTIF(2학년!$A:$A,$A31) -> 0 | D31: =COUNTIF(3학년!$A:$A,$A31) -> 23 | E31: =COUNTIF(4학년!$A:$A,$A31) -> 23 | F31: =COUNTIF(5학년!$A:$A,$A31) -> 26 | G31: =COUNTIF(6학년!$A:$A,$A31) -> 26 | H31: =SUM(B31:G31) -> 98
A32: 음악 | B32: =COUNTIF(1학년!$A:$A,$A32) -> 0 | C32: =COUNTIF(2학년!$A:$A,$A32) -> 0 | D32: =COUNTIF(3학년!$A:$A,$A32) -> 13 | E32: =COUNTIF(4학년!$A:$A,$A32) -> 13 | F32: =COUNTIF(5학년!$A:$A,$A32) -> 13 | G32: =COUNTIF(6학년!$A:$A,$A32) -> 13 | H32: =SUM(B32:G32) -> 52
A33: 미술 | B33: =COUNTIF(1학년!$A:$A,$A33) -> 0 | C33: =COUNTIF(2학년!$A:$A,$A33) -> 0 | D33: =COUNTIF(3학년!$A:$A,$A33) -> 13 | E33: =COUNTIF(4학년!$A:$A,$A33) -> 13 | F33: =COUNTIF(5학년!$A:$A,$A33) -> 13 | G33: =COUNTIF(6학년!$A:$A,$A33) -> 13 | H33: =SUM(B33:G33) -> 52
A34: 합계 | B34: =SUM(B25:B33) -> 21 | C34: =SUM(C25:C33) -> 40 | D34: =SUM(D25:D33) -> 132 | E34: =SUM(E25:E33) -> 137 | F34: =SUM(F25:F33) -> 160 | G34: =SUM(G25:G33) -> 160 | H34: =SUM(H25:H33) -> 650
A35: 미배치 | H35: =COUNTA(미배치!$D:$D)-1 -> 7 | I35: ← 2026 계획서에 해당 단원 없음

Sheet 과목·영역별
A1: 교과 | B1: 영역 | C1: 학년 | D1: 학기 | E1: 단원 | F1: 코드 | G1: 성취기준 | H1: 구분 | I1: 학년군
A2: 국어 | B2: (1) 듣기⋅말하기 | C2: 1학년 | D2: 1학기 | E2: 5. 반갑게 인사해요 | F2: [2국01-05] | G2: 듣기와 말하기에 관심과 흥미를 가진다. | H2: 두 학년 공통 | I2: 1~2학년군
A3: 국어 | B3: (1) 듣기⋅말하기 | C3: 2학년 | D3: 1학기 | E3: 1. 만나서 반가워요! | F3: [2국01-03] | G3: 상대의 말을 집중하여 듣고 말차례를 지키며 대화한다. | H3: 단일 학년 | I3: 1~2학년군
A4: 국어 | B4: (1) 듣기⋅말하기 | C4: 2학년 | D4: 1학기 | E4: 6. 자신의 생각을 표현해요 | F4: [2국01-04] | G4: 자신의 경험이나 생각을 바른 자세로 발표한다. | H4: 단일 학년 | I4: 1~2학년군
A5: 국어 | B5: (1) 듣기⋅말하기 | C5: 2학년 | D5: 1학기 | E5: 1. 만나서 반가워요! | F5: [2국01-05] | G5: 듣기와 말하기에 관심과 흥미를 가진다. | H5: 두 학년 공통 | I5: 1~2학년군
A6: 국어 | B6: (1) 듣기⋅말하기 | C6: 2학년 | D6: 2학기 | E6: 5. 바른 말로 이야기 나누어요 | F6: [2국01-01] | G6: 중요한 내용이나 일이 일어난 순서를 고려하며 듣고 말한다. | H6: 단일 학년 | I6: 1~2학년군
A7: 국어 | B7: (1) 듣기⋅말하기 | C7: 2학년 | D7: 2학기 | E7: 2. 서로 존중해요 | F7: [2국01-02] | G7: 바르고 고운 말로 서로의 감정을 나누며 듣고 말한다. | H7: 단일 학년 | I7: 1~2학년군
A8: 국어 | B8: (1) 듣기⋅말하기 | C8: 3학년 | D8: 1학기 | E8: 4. 중요한 내용을 찾아요 › 1. 중요한 내용을 파악하며 듣기 | F8: [4국01-01] | G8: 중요한 내용과 주제를 파악하며 듣고 그 내용을 요약한다. | H8: 단일 학년 | I8: 3~4학년군
A9: 국어 | B9: (1) 듣기⋅말하기 | C9: 3학년 | D9: 2학기 | E9: 4. 서로 존중하며 대화해요 › 1. 높임 표현을 바르게 사용하기 | F9: [4국01-03] | G9: 상황에 적절한 준언어⋅비언어적 표현을 활용하여 듣고 말한다. | H9: 단일 학년 | I9: 3~4학년군
A10: 국어 | B10: (1) 듣기⋅말하기 | C10: 3학년 | D10: 2학기 | E10: 4. 서로 존중하며 대화해요 | F10: [4국01-04] | G10: 상황과 상대의 입장을 이해하고 예의를 지키며 대화한다. | H10: 단일 학년 | I10: 3~4학년군
A11: 국어 | B11: (1) 듣기⋅말하기 | C11: 3학년 | D11: 2학기 | E11: 6. 감상과 표현의 즐거움 › 2. 의견을 제시하는 글 쓰기 | F11: [4국01-06] | G11: 주제에 적절한 의견과 이유를 제시하고 서로의 생각을 교환하며 토의한다. | H11: 두 학년 공통 | I11: 3~4학년군
A12: 국어 | B12: (1) 듣기⋅말하기 | C12: 4학년 | D12: 1학기 | E12: 5. 말과 글로 전하는 생각 › 1. 자신 있게 발표하기 | F12: [4국01-05] | G12: 목적과 주제에 알맞게 자료를 정리하여 자신감 있게 발표한다. | H12: 단일 학년 | I12: 3~4학년군
... A658: 미술 | B658: (3) 감상 | C658: 6학년 | D658: 2학기 | E658: 10. 지붕 없어도 미술관 | F658: [6미03-03] | G658: 공동체의 미술 문화 활동에 관심을 가지고 참여하며 경험을 공유할 수 있다. | H658: 두 학년 반복·심화 | I658: 5~6학년군

Sheet 내용 체계 도식
A1: 학년별 내용 체계 도식 — 교과 › 영역 × 학년. 셀: [학기] 단원 (성취기준 코드). 사회·과학은 2022 개정 내용 영역으로 재분류
A3: 국어 (87개) | B3: 1학년 | C3: 2학년 | D3: 3학년 | E3: 4학년 | F3: 5학년 | G3: 6학년
A4: 듣기·말하기 (18개) | B4: [1] 반갑게 인사해요 2국01-05 | C4: [1] 만나서 반가워요! 2국01-03 2국01-05 [1] 자신의 생각을 표현해요 2국01-04 [2] 바른 말로 이야기 나누어요 2국01-01 [2] 서로 존중해요 2국01-02 | D4: [1] 중요한 내용을 찾아요 4국01-01 [2] 서로 존중하며 대화해요 4국01-03 4국01-04 [2] 감상과 표현의 즐거움 4국01-06 | E4: [1] 말과 글로 전하는 생각 4국01-05 [1] 서로 다른 의견 4국01-06 [2] 상상의 날개 4국01-02 | F4: [1] 대화를 나누어요 6국01-01 [1] 발표하고 질문해요 6국01-03 6국01-05 [2] 의견을 조정해요 6국01-06 | G4: [1] 절차를 지키며 토론해요 6국01-07 [2] 보거나 듣고 판단해요 6국01-02 [2] 궁금한 점을 해결해요 6국01-03 6국01-04
A5: 읽기 (16개) | B5: [1] 또박또박 읽어요 2국02-01 2국02-05 [2] 낱말을 정확하게 읽어요 2국02-01 | C5: [1] 마음을 짐작해요 2국02-02 2국02-04 [1] 분위기를 살려 읽어요 2국02-05 [2] 내용을 살펴요 2국02-03 | D5: [1] 자신 있게 읽고 써요 4국02-04 [1] 독서: 읽은 책을 소개해요 4국02-06 [2] 유창하게 읽고 발표해요 4국02-01 [2] 정확하게 글을 써요 4국02-05 [2] 독서: 계획대로 차근차근 읽어요 4국02-06 | E5: [1] 뜻을 파악하며 읽어요 4국02-02 [1] 독서: 질문을 만들며 책을 읽어요 4국02-03 4국02-06 [2] 독서: 생각을 나누며 책을 읽어요 4국02-06 | F5: [1] 대상을 설명해요 6국02-01 [1] 대화를 나누어요 6국02-02 [1] 의논하며 토의해요 6국02-04 | G5: [1] 비판적으로 읽어요 6국02-03 6국02-05
A6: 쓰기 (15개) | B6: [1] 글자를 만들어요 2국03-01 | C6: [1] 자신의 생각을 표현해요 2국03-02 [1] 겪은 일을 나타내요 2국03-04 [2] 내용을 살펴요 2국03-03 | D6: [1] 짜임새 있는 글, 재미와 감동이 있는 글 4국03-01 [1] 인물에게 마음을 전해요 4국03-04 [1] 자신 있게 읽고 써요 4국03-05 | E6: [1] 자세하게 살펴요 4국03-02 [1] 말과 글로 전하는 생각 4국03-03 | F6: [1] 대상을 설명해요 6국03-01 6국03-05 [1] 체험한 일을 글로 써요 6국03-03 [2] 올바른 문장으로 글을 써요 6국03-04 | G6: [1] 자신의 글쓰기 과정을 살펴봐요 6국03-02 [1] 바르게 고쳐 써요 6국03-05 [2] 언어와 소통 6국03-04 6국03-06
A7: 문법 (14개) | B7: [1] 한글 놀이 2국04-01 [1] 글자를 만들어요 2국04-01 [1] 받침이 있는 글자를 읽어요 2국04-02 [1] 또박또박 읽어요 2국04-03 [2] 문장을 읽고 써요 2국04-02 | D7: [1] 분명하고 유창하게 4국04-03 [2] 사전으로 여는 세상 4국04-02 [2] 서로 존중하며 대화해요 4국04-04 | E7: [1] 자세하게 살펴요 4국04-01 [2] 우리말 우리글 4국04-05 | F7: [2] 표준어와 방언을 알아봐요 6국04-02 | G7: [1] 상황에 맞게 표현해요 6국04-03 6국04-05 [1] 바르게 고쳐 써요 6국04-04 6국04-06 [2] 언어와 소통 6국04-01
A8: 문학 (15개) | B8: [2] 감동을 나누어요 2국05-04 | C8: [1] 말의 재미가 솔솔 2국05-01 [1] 다양한 작품을 감상해요 2국05-02 [2] 장면을 상상하며 2국05-03 [2] 나도 작가 2국05-04 | D8: [1] 짜임새 있는 글, 재미와 감동이 있는 글 4국05-03 4국05-05 | E8: [1] 깊이 있게 읽어요 4국05-01 [1] 경험을 표현해요 4국05-04 [2] 비교하며 읽어요 4국05-02 [2] 책 속의 길을 따라 4국05-03 | F8: [1] 작품을 즐겨요 6국05-02 [2] 작품을 감상해요 6국05-01 6국05-03 [2] 작품에 대한 의견을 나누어요 6국05-04 | G8: [1] 자신의 글쓰기 과정을 살펴봐요 6국05-05 [1] 자신의 삶과 관련지어 읽어요 6국05-06 [2] 깊이 있게 감상해요 6국05-01
A9: 매체 (9개) | C9: [2] 매체를 경험해요 2국06-01 2국06-02 | D9: [2] 유창하게 읽고 발표해요 4국06-02 | E9: [1] 자세하게 살펴요 4국06-01 [2] 의견을 모아서 4국06-02 4국06-03 | F9: [1] 발표하고 질문해요 6국06-01 [2] 매체: 판단하며 이용해요 6국06-02 | G9: [1] 절차를 지키며 토론해요 6국06-03 [2] 매체: 매체 이용 습관을 돌아봐요 6국06-04
A11: 수학 (121개) | B11: 1학년 | C11: 2학년 | D11: 3학년 | E11: 4학년 | F11: 5학년 | G11: 6학년
A12: 수와 연산 (42개) | B12: [1] 9까지의 수 2수01-01 [1] 50까지의 수 2수01-01 [1] 덧셈과 뺄셈 2수01-04 2수01-05 2수01-07 [2] 100까지의 수 2수01-01 [2] 덧셈과 뺄셈(1) 2수01-06 [2] 덧셈과 뺄셈(3) 2수01-08 | C12: [1] 세 자리 수 2수01-02 [1] 덧셈과 뺄셈 2수01-06 2수01-07 2수01-08 2수01-09 [1] 곱셈 2수01-10 [2] 네 자리 수 2수01-02 2수01-03 [2] 곱셈구구 2수01-11 | D12: [1] 덧셈과 뺄셈 4수01-03 4수01-08 [1·2] 곱셈 4수01-04 [1·2] 나눗셈 4수01-05 4수01-06 [1] 분수와 소수 4수01-09 4수01-11 4수01-12 [2] 분수 4수01-10 4수01-11 | E12: [1] 큰 수 4수01-01 4수01-02 [1] 곱셈과 나눗셈 4수01-04 4수01-07 4수01-08 [2] 소수의 덧셈과 뺄셈 4수01-13 4수01-14 4수01-16 [2] 분수의 덧셈과 뺄셈 4수01-15 | F12: [1] 자연수의 혼합 계산 6수01-01 [1] 약수와 배수 6수01-04 6수01-05 [1] 약분과 통분 6수01-06 6수01-07 [1] 분수의 덧셈과 뺄셈 6수01-08 [2] 수의 범위와 어림하기 6수01-02 6수01-03 [2] 분수의 곱셈 6수01-09 [2] 소수의 곱셈 6수01-12 6수01-13 | G12: [1·2] 분수의 나눗셈 6수01-10 6수01-11 [1·2] 소수의 나눗셈 6수01-12 6수01-14 6수01-15
A13: 변화와 관계 (10개) | B13: [2] 규칙 찾기 2수02-01 2수02-02 | C13: [2] 규칙 찾기 2수02-02 | E13: [1] 규칙과 관계 4수02-01 4수02-02 4수02-03 | F13: [1] 대응 관계 6수02-01 | G13: [1] 비와 비율 6수02-02 6수02-03 [2] 비례식과 비례배분 6수02-04 6수02-05
A14: 도형과 측정 (57개) | B14: [1] 여러 가지 모양 2수03-01 2수03-03 [1] 비교하기 2수03-06 [2] 모양과 시각 2수03-04 2수03-07 | C14: [1] 여러 가지 도형 2수03-02 2수03-04 2수03-05 [1·2] 길이 재기 2수03-10 2수03-11 2수03-12 2수03-13 [2] 시각과 시간 2수03-07 2수03-08 2수03-09 | D14: [1] 평면도형 4수03-01 4수03-02 [1] 길이와 시간 4수03-13 4수03-14 4수03-15 4수03-16 [2] 원 4수03-06 4수03-07 [2] 들이와 무게 4수03-17 4수03-18 4수03-19 4수03-20 4수03-21 4수03-22 4수03-23 | E14: [1] 각도 4수03-02 4수03-24 [1] 평면도형의 이동 4수03-04 4수03-05 [2] 사각형 4수03-03 4수03-10 [2] 삼각형 4수03-08 4수03-09 4수03-25 [2] 다각형 4수03-11 4수03-12 | F14: [1] 다각형의 둘레와 넓이 6수03-11 6수03-12 6수03-13 6수03-14 [2] 합동과 대칭 6수03-01 6수03-02 [2] 직육면체 6수03-03 6수03-04 | G14: [1] 각기둥과 각뿔 6수03-05 6수03-06 [1] 직육면체의 부피와 겉넓이 6수03-17 6수03-18 6수03-19 [2] 원기둥, 원뿔, 구 6수03-07 6수03-08 [2] 공간과 입체 6수03-09 6수03-10 [2] 원의 둘레와 넓이 6수03-15 6수03-16
A15: 자료와 가능성 (12개) | C15: [1] 분류하기 2수04-01 [2] 표와 그래프 2수04-02 2수04-03 | D15: [2] 그림그래프 4수04-01 | E15: [1] 막대그래프 4수04-01 [2] 꺾은선그래프 4수04-02 4수04-03 | F15: [2] 평균과 가능성 6수04-01 6수04-04 6수04-05 6수04-06 | G15: [1] 여러 가지 그래프 6수04-02 6수04-03
A17: 사회 (49개) | B17: 1학년 | C17: 2학년 | D17: 3학년 | E17: 4학년 | F17: 5학년 | G17: 6학년
A18: 지리 인식 (8개) | D18: [1] 우리가 사는 곳 (여러 장소, 생활에 도움을 주는 장소) 4사01-01 4사01-02 | E18: [1] 지도로 만나는 우리 지역 (지도, 우리 지역의 위치와 특성) 4사05-01 4사05-02 | F18: [1] 우리나라의 지형·기후와 자연재해 6사01-01 [1] 국토의 위치와 지리 탐구 (국토 여행, 독도) 6사01-02 | G18: [1] 세계를 표현하는 자료, 세계 여러 국가의 위치와 영토 6사09-01 6사09-02 [2] 지구촌 사람들 (인구 분포, 지구촌 문제와 지속가능한 미래) 6사01-02
A19: 자연환경과 인간 생활 (6개) | E19: [2] 지역문제를 해결하고 지역을 알리는 노력 4사10-01 4사10-02 | F19: [1] 우리나라의 지형·기후와 자연재해 6사02-01 [1] 우리나라의 인구 분포 6사02-02 | G19: [2] 세계의 자연환경 (지형 경관, 기후와 생활 모습) 6사10-01 6사10-02
A20: 지속가능한 세계 (4개) | E20: [2] 지역문제를 해결하고 지역을 알리는 노력 4사09-01 4사09-02 | G20: [2] 지구촌 사람들 (인구 분포, 지구촌 문제와 지속가능한 미래) 6사12-01 6사12-02
A21: 역사 (17개) | D21: [1] 일상에서 만나는 과거 (시간의 흐름, 과거의 모습, 달라진 생활 모습) 4사02-01 4사02-02 4사02-03 [2] 옛날과 오늘날의 풍습·생활 모습 4사04-01 [2] 사회 변화로 달라진 생활 모습 (교통·통신의 변화) 4사04-02 4사04-03 | E21: [1] 우리 지역의 국가유산·역사 4사06-01 4사06-02 | F21: [2] 유적과 유물로 살펴본 옛 사람들의 생활 (선사·고조선, 고대, 고려) 6사04-01 6사04-02 6사04-03 [2] 달라지는 시대, 변화하는 생활 모습 (조선, 조선 후기·개항) 6사05-01 6사05-02 [2] 식민 통치와 저항, 전쟁이 바꾼 사회와 생활 6사06-01 6사06-02 | G21: [1] 평화 통일을 위한 노력, 민주화와 산업화 6사07-01 6사07-02
A22: 정치 (5개) | E22: [2] 민주주의와 자치 (학교생활 속 민주주의, 주민 자치) 4사08-01 4사08-02 | G22: [1] 민주주의와 선거·국가기관·시민 참여·미디어 6사08-01 6사08-02 6사08-03
A23: 법 (2개) | F23: [1] 법의 역할과 인권 (인권 보호, 법과 인권의 보장) 6사03-01 6사03-02
A24: 경제 (5개) | E24: [1] 경제활동과 지역 간 교류 4사07-01 4사07-02 | G24: [2] 시장경제와 국가 간 거래 (시장경제, 경제성장, 무역) 6사11-01 6사11-02 6사11-03
A25: 사회·문화 (2개) | D25: [2] 사회 변화로 달라진 생활 모습 (교통·통신의 변화) 4사03-01 4사03-02
A27: 과학 (102개) | B27: 1학년 | C27: 2학년 | D27: 3학년 | E27: 4학년 | F27: 5학년 | G27: 6학년
A28: 운동과 에너지 (21개) | D28: [1] 힘과 우리 생활 4과01-01 4과01-02 4과01-03 4과01-04 [2] 소리의 성질 4과07-01 4과07-02 4과07-03 | E28: [1] 자석의 이용 4과09-01 4과09-02 4과09-03 | F28: [1] 빛의 성질 6과02-01 6과02-02 6과02-03 [2] 열과 우리 생활 6과07-01 6과07-02 6과07-03 6과07-04 | G28: [2] 보충: 빛의 성질·우리 몸의 구조와 기능·자원과 에너지 6과02-01 6과02-02 6과02-03 [2] 전기의 이용 6과15-01 6과15-02 6과15-03 6과15-04
A29: 물질 (20개) | D29: [2] 물체와 물질 4과05-01 4과05-02 4과05-03 | E29: [1] 물의 상태 변화 4과10-01 4과10-02 4과10-03 [2] 여러 가지 기체 4과15-01 4과15-02 4과15-03 4과15-04 | F29: [1] 용해와 용액 6과03-01 6과03-02 6과03-03 [2] 혼합물의 분리 6과05-01 6과05-02 6과05-03 | G29: [2] 물질의 연소 6과14-01 6과14-02 6과14-03 6과14-04
A30: 생명 (21개) | D30: [1] 동물의 생활 4과02-01 4과02-02 4과02-03 [1] 식물의 생활 4과03-01 4과03-02 4과03-03 [1] 생물의 한살이 4과04-01 4과04-02 4과04-03 | E30: [1] 다양한 생물과 우리 생활 4과12-01 4과12-02 4과12-03 [2] 생물과 환경 4과14-01 4과14-02 4과14-03 | F30: [1] 우리 몸의 구조와 기능 6과04-01 6과04-02 6과04-03 | G30: [1] 식물의 구조와 기능 6과11-01 6과11-02 6과11-03 [2] 보충: 빛의 성질·우리 몸의 구조와 기능·자원과 에너지 6과04-02 6과04-03
A31: 지구와 우주 (22개) | D31: [2] 지구와 바다 4과06-01 4과06-02 4과06-03 | E31: [1] 땅의 변화 4과11-01 4과11-02 4과11-03 4과11-04 [2] 밤하늘 관찰 4과13-01 4과13-02 4과13-03 | F31: [1] 지층과 화석 6과01-01 6과01-02 6과01-03 [2] 날씨와 우리 생활 6과06-01 6과06-02 6과06-03 | G31: [1] 지구의 운동 6과12-01 6과12-02 6과12-03 6과13-01 6과13-02 6과13-03
A32: 과학과 사회 (11개) | D32: [2] 감염병과 건강한 생활 4과08-01 4과08-02 4과08-03 | E32: [2] 기후변화와 우리 생활 4과16-01 4과16-02 4과16-03 | F32: [2] 자원과 에너지 6과08-01 6과08-02 6과08-03 | G32: [2] 보충: 빛의 성질·우리 몸의 구조와 기능·자원과 에너지 6과08-01 6과08-02 6과08-03 [2] 과학과 나의 진로 6과16-01 6과16-02
A33: 미배치: [6과09-01] 산과 염기, [6과09-02] 산과 염기, [6과09-03] 산과 염기, [6과09-04] 산과 염기, [6과10-01] 물체의 운동, [6과10-02] 물체의 운동, [6과10-03] 물체의 운동
A35: 도덕 (24개) | B35: 1학년 | C35: 2학년 | D35: 3학년 | E35: 4학년 | F35: 5학년 | G35: 6학년
A36: 자신과의 관계 (7개) | D36: [1] 나를 찾아 떠나는 여행 4도01-01 [1] 성실하게 사는 삶 4도01-03 | E36: [1] 바르고 곧은 길 4도01-02 [1] 도덕적인 나 4도01-04 | F36: [1] 내 삶의 주인이 되는 나 6도01-01 [1] 반성과 성찰로 성장하는 나 6도01-02 | G36: [1] 나는 꿈 요리사 6도01-03
A37: 타인과의 관계 (6개) | D37: [1] 함께하는 우리 가족 4도02-01 [2] 너와 나의 공감 4도02-03 | E37: [1] 배려하는 우리 4도02-02 [1] 도덕적인 나 4도02-03 | F37: [1] 함께 사는 세상, 봉사하는 우리 6도02-01 | G37: [1] 다름을 존중하는 우리 6도02-02 [1] 인공지능 로봇 그리고 나 6도02-03
A38: 사회·공동체와의 관계 (7개) | D38: [2] 함께 가는 공정의 길 4도03-01 | E38: [2] 바람직한 디지털 사회 4도03-02 [2] 통일로 가는 한 걸음 4도03-03 | F38: [2] 모두에게 인권을 6도03-01 [2] 공동체를 정의롭게! 6도03-02 | G38: [2] 통일 한반도의 어느 날 6도03-03 [2] 사랑, 우리를 넘어 세계로 6도03-04
A39: 자연과의 관계 (4개) | D39: [2] 생명을 소중히 여기는 우리 4도04-01 | E39: [2] 자연은 소중해요 4도04-02 | F39: [2] 지구의 내일을 심는 우리 6도04-01 | G39: [2] 우리 모두의 미래를 위한 선택 6도04-02
A41: 실과 (39개) | B41: 1학년 | C41: 2학년 | D41: 3학년 | E41: 4학년 | F41: 5학년 | G41: 6학년
A42: 인간 발달과 주도적 삶 (7개) | F42: [1] 건강한 발달과 생활 (발달·식생활·의생활) 6실01-01 6실01-02 6실01-04 6실01-05 | G42: [1] 가정생활과 진로 6실01-03 6실01-06 6실01-07
A43: 생활환경과 지속가능한 선택 (11개) | F43: [1] 생활자원과 생활 공간 관리 6실02-01 6실02-02 6실02-03 6실02-07 6실02-08 6실02-10 [2] 식생활과 의생활의 실천 6실02-05 6실02-09 | G43: [1] 지속가능한 선택 6실02-10 6실02-11 [2] 식생활과 의생활 6실02-04 6실02-06
A44: 기술적 문제해결과 혁신 (5개) | F44: [2] 우리 생활과 수송 6실03-04 6실03-05 | G44: [2] 발명과 특허 6실03-01 6실03-02 6실03-03
A45: 지속가능한 기술과 융합 (11개) | F45: [1] 생활 속 동물과 식물 6실04-07 6실04-08 [2] 건설 기술과 디지털 기술 6실04-01 6실04-02 6실04-03 | G45: [1] 농업 활동과 미래 6실04-09 6실04-10 6실04-11 [2] 로봇과 융합 기술 6실04-04 6실04-05 6실04-06
A46: 디지털 사회와 인공지능 (5개) | F46: [2] 컴퓨터와 문제 해결 6실05-01 6실05-02 6실05-03 | G46: [2] 생활 속 인공지능 6실05-04 6실05-05
...

Sheet 1학년
A1: 교과 | B1: 학기 | C1: 단원 | D1: 영역 | E1: 코드 | F1: 성취기준 | G1: 구분 | H1: 근거
A2: 국어 | B2: 1학기 | C2: 5. 반갑게 인사해요 | D2: (1) 듣기⋅말하기 | E2: [2국01-05] | F2: 듣기와 말하기에 관심과 흥미를 가진다. | G2: 두 학년 공통 | H2: 검토 보정
A3: 국어 | B3: 1학기 | C3: 6. 또박또박 읽어요 | D3: (2) 읽기 | E3: [2국02-05] | F3: 읽기에 흥미를 가지고 즐겨 읽는 태도를 지닌다. | G3: 두 학년 공통 | H3: 검토 보정
A4: 국어 | B4: 1학기 | C4: 1. 글자를 만들어요 | D4: (3) 쓰기 | E4: [2국03-01] | F4: 글자와 단어를 바르게 쓴다. | G4: 단일 학년 | H4: 자동 대조
A5: 국어 | B5: 1학기 | C5: 한글 놀이 1. 글자를 만들어요 | D5: (4) 문법 | E5: [2국04-01] | F5: 한글 자모의 이름과 소릿값을 알고 정확하게 발음하고 쓴다. | G5: 단일 학년 | H5: 검토 보정
A6: 국어 | B6: 1학기 | C6: 6. 또박또박 읽어요 | D6: (4) 문법 | E6: [2국04-03] | F6: 문장과 문장 부호를 알맞게 쓰고 한글에 호기심을 가진다. | G6: 단일 학년 | H6: 자동 대조
A7: 수학 | B7: 1학기 | C7: 3. 덧셈과 뺄셈 | D7: (1) 수와 연산 | E7: [2수01-04] | F7: 하나의 수를 두 수로 분해하고 두 수를 하나의 수로 합성하는 활동을 통하여 수 감각을 기른다. | G7: 단일 학년 | H7: 검토 보정
A8: 수학 | B8: 1학기 | C8: 3. 덧셈과 뺄셈 | D8: (1) 수와 연산 | E8: [2수01-05] | F8: 덧셈과 뺄셈이 이루어지는 실생활 상황과 연결하여 덧셈과 뺄셈의 의미를 이해한다. | G8: 단일 학년 | H8: 검토 보정
A9: 수학 | B9: 1학기 | C9: 3. 덧셈과 뺄셈 | D9: (1) 수와 연산 | E9: [2수01-07] | F9: 덧셈과 뺄셈의 관계를 이해한다. | G9: 두 학년 공통 | H9: 검토 보정
A10: 수학 | B10: 1학기 | C10: 2. 여러 가지 모양 | D10: (3) 도형과 측정 | E10: [2수03-01] | F10: 교실 및 생활 주변에서 여러 가지 물건을 관찰하여 직육면체, 원기둥, 구의 모양을 찾고, 이를 이용하여 여러 가지 모양을 만들 수 있다. | G10: 단일 학년 | H10: 검토 보정
A11: 수학 | B11: 1학기 | C11: 2. 여러 가지 모양 | D11: (3) 도형과 측정 | E11: [2수03-03] | F11: 교실 및 생활 주변에서 여러 가지 물건을 관찰하여 삼각형, 사각형, 원의 모양을 찾고, 이를 이용하여 여러 가지 모양을 만들 수 있다. | G11: 단일 학년 | H11: 검토 보정
A12: 수학 | B12: 1학기 | C12: 4. 비교하기 | D12: (3) 도형과 측정 | E12: [2수03-06] | F12: 구체물의 길이, 들이, 무게, 넓이를 비교하여 각각 ‘길다, 짧다’, ‘많다, 적다’, ‘무겁다, 가볍다’, ‘넓다, 좁다’ 등을 구별하여 말할 수 있다. | G12: 단일 학년 | H12: 검토 보정
... A22: 수학 | B22: 2학기 | C22: 3. 모양과 시각 | D22: (3) 도형과 측정 | E22: [2수03-07] | F22: 시계를 보고 시각을 ‘몇 시 몇 분’까지 읽을 수 있다. | G22: 두 학년 공통 | H22: 검토 보정

Sheet 2학년
A1: 교과 | B1: 학기 | C1: 단원 | D1: 영역 | E1: 코드 | F1: 성취기준 | G1: 구분 | H1: 근거
A2: 국어 | B2: 1학기 | C2: 1. 만나서 반가워요! | D2: (1) 듣기⋅말하기 | E2: [2국01-03] | F2: 상대의 말을 집중하여 듣고 말차례를 지키며 대화한다. | G2: 단일 학년 | H2: 자동 대조
A3: 국어 | B3: 1학기 | C3: 6. 자신의 생각을 표현해요 | D3: (1) 듣기⋅말하기 | E3: [2국01-04] | F3: 자신의 경험이나 생각을 바른 자세로 발표한다. | G3: 단일 학년 | H3: 자동 대조
A4: 국어 | B4: 1학기 | C4: 1. 만나서 반가워요! | D4: (1) 듣기⋅말하기 | E4: [2국01-05] | F4: 듣기와 말하기에 관심과 흥미를 가진다. | G4: 두 학년 공통 | H4: 검토 보정
A5: 국어 | B5: 1학기 | C5: 5. 마음을 짐작해요 | D5: (2) 읽기 | E5: [2국02-02] | F5: 의미가 잘 드러나도록 문장과 짧은 글을 알맞게 띄어 읽는다. | G5: 단일 학년 | H5: 자동 대조
A6: 국어 | B6: 1학기 | C6: 5. 마음을 짐작해요 | D6: (2) 읽기 | E6: [2국02-04] | F6: 인물의 마음이나 생각을 짐작하고 이를 자신과 비교하며 글을 읽는다. | G6: 단일 학년 | H6: 자동 대조
A7: 국어 | B7: 1학기 | C7: 4. 분위기를 살려 읽어요 | D7: (2) 읽기 | E7: [2국02-05] | F7: 읽기에 흥미를 가지고 즐겨 읽는 태도를 지닌다. | G7: 두 학년 공통 | H7: 검토 보정
A8: 국어 | B8: 1학기 | C8: 6. 자신의 생각을 표현해요 | D8: (3) 쓰기 | E8: [2국03-02] | F8: 쓰기에 흥미를 가지며 자신의 생각이나 느낌을 문장으로 표현한다. | G8: 단일 학년 | H8: 자동 대조
A9: 국어 | B9: 1학기 | C9: 3. 겪은 일을 나타내요 | D9: (3) 쓰기 | E9: [2국03-04] | F9: 겪은 일을 표현하는 글을 자유롭게 쓰고, 쓴 글을 함께 읽고 생각이나 느낌을 나눈다. | G9: 단일 학년 | H9: 자동 대조
A10: 국어 | B10: 1학기 | C10: 2. 말의 재미가 솔솔 | D10: (5) 문학 | E10: [2국05-01] | F10: 말놀이, 낭송 등을 통해 말의 재미와 즐거움을 느낀다. | G10: 단일 학년 | H10: 자동 대조
A11: 국어 | B11: 1학기 | C11: 8. 다양한 작품을 감상해요 | D11: (5) 문학 | E11: [2국05-02] | F11: 작품을 듣거나 읽으면서 느끼거나 생각한 점을 말한다. | G11: 단일 학년 | H11: 자동 대조
A12: 수학 | B12: 1학기 | C12: 3. 덧셈과 뺄셈 | D12: (1) 수와 연산 | E12: [2수01-06] | F12: 두 자리 수의 범위에서 덧셈과 뺄셈의 계산 원리를 이해하고 그 계산을 할 수 있다. | G12: 두 학년 공통 | H12: 검토 보정
... A41: 수학 | B41: 2학기 | C41: 5. 표와 그래프 | D41: (4) 자료와 가능성 | E41: [2수04-03] | F41: 자료를 분류하여 ○, ×, / 등을 이용한 그래프로 나타내고, 자료를 그래프로 나타내면 편리한 점을 말할 수 있다. | G41: 단일 학년 | H41: 자동 대조

Sheet 3학년
A1: 교과 | B1: 학기 | C1: 단원 | D1: 영역 | E1: 코드 | F1: 성취기준 | G1: 구분 | H1: 근거
A2: 국어 | B2: 1학기 | C2: 4. 중요한 내용을 찾아요 › 1. 중요한 내용을 파악하며 듣기 | D2: (1) 듣기⋅말하기 | E2: [4국01-01] | F2: 중요한 내용과 주제를 파악하며 듣고 그 내용을 요약한다. | G2: 단일 학년 | H2: 자동 대조
A3: 국어 | B3: 1학기 | C3: 6. 자신 있게 읽고 써요 › 1. 사실과 의견 구분하기 | D3: (2) 읽기 | E3: [4국02-04] | F3: 글에 나타난 사실과 의견을 구분하고 필자와 자신의 의견을 비교한다. | G3: 단일 학년 | H3: 자동 대조
A4: 국어 | B4: 1학기 | C4: 3. 짜임새 있는 글, 재미와 감동이 있는 글 › 1. 짜임새 있는 문단 쓰기 | D4: (3) 쓰기 | E4: [4국03-01] | F4: 중심 문장과 뒷받침 문장을 갖추어 문단을 쓰고, 문장과 문단을 중심으로 고쳐 쓴다. | G4: 단일 학년 | H4: 자동 대조
A5: 국어 | B5: 1학기 | C5: 5. 인물에게 마음을 전해요 › 2. 마음을 전하는 글 쓰기 | D5: (3) 쓰기 | E5: [4국03-04] | F5: 목적과 주제를 고려하여 독자에게 마음을 전하는 글을 쓴다. | G5: 단일 학년 | H5: 자동 대조
A6: 국어 | B6: 1학기 | C6: 6. 자신 있게 읽고 써요 | D6: (3) 쓰기 | E6: [4국03-05] | F6: 자신의 쓰기 과정을 점검하며 쓰기에 자신감을 갖는다. | G6: 단일 학년 | H6: 자동 대조
A7: 국어 | B7: 1학기 | C7: 2. 분명하고 유창하게 | D7: (4) 문법 | E7: [4국04-03] | F7: 기본적인 문장의 짜임을 이해하고 적절하게 사용한다. | G7: 단일 학년 | H7: 자동 대조
A8: 국어 | B8: 1학기 | C8: 3. 짜임새 있는 글, 재미와 감동이 있는 글 › 2. 작품을 읽고 재미나 감동 표현하기 | D8: (5) 문학 | E8: [4국05-03] | F8: 작품을 듣거나 읽고 마음에 드는 작품을 소개한다. | G8: 두 학년 공통 | H8: 자동 대조
A9: 국어 | B9: 1학기 | C9: 3. 짜임새 있는 글, 재미와 감동이 있는 글 › 2. 작품을 읽고 재미나 감동 표현하기 | D9: (5) 문학 | E9: [4국05-05] | F9: 재미나 감동을 느끼며 작품을 즐겨 감상하는 태도를 지닌다. | G9: 단일 학년 | H9: 자동 대조
A10: 수학 | B10: 1학기 | C10: 1. 덧셈과 뺄셈 | D10: (1) 수와 연산 | E10: [4수01-03] | F10: 세 자리 수의 덧셈과 뺄셈의 계산 원리를 이해하고 그 계산을 할 수 있다. | G10: 단일 학년 | H10: 검토 보정
A11: 수학 | B11: 1학기 | C11: 3. 나눗셈 | D11: (1) 수와 연산 | E11: [4수01-05] | F11: 나눗셈이 이루어지는 실생활 상황과 연결하여 나눗셈의 의미를 알고, 곱셈과 나눗셈의 관계를 이해한다. | G11: 단일 학년 | H11: 검토 보정
A12: 수학 | B12: 1학기 | C12: 1. 덧셈과 뺄셈 | D12: (1) 수와 연산 | E12: [4수01-08] | F12: 자연수의 덧셈, 뺄셈, 곱셈, 나눗셈과 관련한 여러 가지 상황에서 어림셈을 할 수 있다. | G12: 두 학년 공통 | H12: 검토 보정
... A133: 미술 | B133: 2학기 | C133: 13. 질문이 예술 | D133: (3) 감상 | E133: [4미03-01] | F133: 미술 작품을 자세히 보고 작품과 미술가에 관해 질문할 수 있다. | G133: 두 학년 반복·심화 | H133: 자동 대조

Sheet 4학년
A1: 교과 | B1: 학기 | C1: 단원 | D1: 영역 | E1: 코드 | F1: 성취기준 | G1: 구분 | H1: 근거
A2: 국어 | B2: 1학기 | C2: 5. 말과 글로 전하는 생각 › 1. 자신 있게 발표하기 | D2: (1) 듣기⋅말하기 | E2: [4국01-05] | F2: 목적과 주제에 알맞게 자료를 정리하여 자신감 있게 발표한다. | G2: 단일 학년 | H2: 자동 대조
A3: 국어 | B3: 1학기 | C3: 2. 서로 다른 의견 | D3: (1) 듣기⋅말하기 | E3: [4국01-06] | F3: 주제에 적절한 의견과 이유를 제시하고 서로의 생각을 교환하며 토의한다. | G3: 두 학년 공통 | H3: 자동 대조
A4: 국어 | B4: 1학기 | C4: 4. 뜻을 파악하며 읽어요 › 2. 글의 중심 생각을 파악하며 읽기 | D4: (2) 읽기 | E4: [4국02-02] | F4: 문단과 글에서 중심 생각을 파악하고 내용을 간추린다. | G4: 단일 학년 | H4: 자동 대조
A5: 국어 | B5: 1학기 | C5: 독서단원: 질문을 만들며 책을 읽어요 | D5: (2) 읽기 | E5: [4국02-03] | F5: 질문을 활용하여 글을 예측하며 읽고 자신의 읽기 과정을 점검한다. | G5: 단일 학년 | H5: 검토 보정
A6: 국어 | B6: 1학기 | C6: 3. 자세하게 살펴요 › 2. 대상을 관찰하여 보고하는 글 쓰기 | D6: (3) 쓰기 | E6: [4국03-02] | F6: 절차와 결과가 드러나게 정확한 표현으로 보고하는 글을 쓴다. | G6: 단일 학년 | H6: 자동 대조
A7: 국어 | B7: 1학기 | C7: 5. 말과 글로 전하는 생각 | D7: (3) 쓰기 | E7: [4국03-03] | F7: 대상에 대한 자신의 의견과 그렇게 생각한 이유가 드러나게 글을 쓴다. | G7: 단일 학년 | H7: 검토 보정
A8: 국어 | B8: 1학기 | C8: 3. 자세하게 살펴요 › 1. 낱말의 의미 관계 알기 | D8: (4) 문법 | E8: [4국04-01] | F8: 단어와 단어 간의 의미 관계를 파악한다. | G8: 단일 학년 | H8: 자동 대조
A9: 국어 | B9: 1학기 | C9: 1. 깊이 있게 읽어요 | D9: (5) 문학 | E9: [4국05-01] | F9: 인물과 이야기의 흐름을 중심으로 작품을 감상한다. | G9: 단일 학년 | H9: 자동 대조
A10: 국어 | B10: 1학기 | C10: 6. 경험을 표현해요 | D10: (5) 문학 | E10: [4국05-04] | F10: 감각적 표현에 유의하여 작품을 감상하고, 감각적 표현을 활용하여 자신의 생각이나 감정을 표현한다. | G10: 단일 학년 | H10: 자동 대조
A11: 국어 | B11: 1학기 | C11: 3. 자세하게 살펴요 | D11: (6) 매체 | E11: [4국06-01] | F11: 인터넷에서 학습에 필요한 다양한 자료를 탐색하고 목적에 맞게 자료를 선택한다. | G11: 단일 학년 | H11: 자동 대조
A12: 수학 | B12: 1학기 | C12: 1. 큰 수 | D12: (1) 수와 연산 | E12: [4수01-01] | F12: 큰 수의 필요성을 인식하면서 10000 이상의 큰 수에 대한 자릿값과 위치적 기수법을 이해하고, 수를 읽고 쓸 수 있다. | G12: 단일 학년 | H12: 자동 대조
... A138: 미술 | B138: 2학기 | C138: 여러 단원 공통 | D138: (2) 표현 | E138: [4미02-05] | F138: 미술과 타 교과를 관련지어 주제를 표현하는데 흥미를 가질 수 있다. | G138: 두 학년 반복·심화 | H138: 자동 대조

Sheet 5학년
A1: 교과 | B1: 학기 | C1: 단원 | D1: 영역 | E1: 코드 | F1: 성취기준 | G1: 구분 | H1: 근거
A2: 국어 | B2: 1학기 | C2: 1. 대화를 나누어요 › 2. 생략된 내용을 짐작하며 대화하기 | D2: (1) 듣기⋅말하기 | E2: [6국01-01] | F2: 대화에서 생략된 내용을 추론하며 듣는다. | G2: 단일 학년 | H2: 자동 대조
A3: 국어 | B3: 1학기 | C3: 3. 발표하고 질문해요 › 2. 궁금한 내용 질문하기 | D3: (1) 듣기⋅말하기 | E3: [6국01-03] | F3: 주제와 관련하여 궁금한 내용을 질문하며 적극적으로 듣고 말한다. | G3: 두 학년 공통 | H3: 자동 대조
A4: 국어 | B4: 1학기 | C4: 3. 발표하고 질문해요 › 1. 자료를 선별하여 발표하기 | D4: (1) 듣기⋅말하기 | E4: [6국01-05] | F4: 자료를 선별하여 핵심 정보를 중심으로 내용을 구성하고 매체를 활용하여 발표한다. | G4: 단일 학년 | H4: 자동 대조
A5: 국어 | B5: 1학기 | C5: 4. 대상을 설명해요 | D5: (2) 읽기 | E5: [6국02-01] | F5: 글의 구조를 고려하며 주제나 주장을 파악하고 글 내용을 요약한다. | G5: 단일 학년 | H5: 검토 보정
A6: 국어 | B6: 1학기 | C6: 1. 대화를 나누어요 › 2. 생략된 내용을 짐작하며 대화하기 | D6: (2) 읽기 | E6: [6국02-02] | F6: 글에서 생략된 내용이나 함축된 표현을 문맥을 고려하여 추론한다. | G6: 단일 학년 | H6: 자동 대조
A7: 국어 | B7: 1학기 | C7: 5. 의논하며 토의해요 | D7: (2) 읽기 | E7: [6국02-04] | F7: 문제 상황과 관련된 다양한 관점의 글을 읽고 이를 문제 해결에 활용한다. | G7: 단일 학년 | H7: 자동 대조
A8: 국어 | B8: 1학기 | C8: 4. 대상을 설명해요 › 2. 대상을 설명하는 글 쓰기 | D8: (3) 쓰기 | E8: [6국03-01] | F8: 알맞은 내용을 선정하여 대상의 특성이 나타나게 설명하는 글을 쓴다. | G8: 단일 학년 | H8: 자동 대조
A9: 국어 | B9: 1학기 | C9: 2. 체험한 일을 글로 써요 | D9: (3) 쓰기 | E9: [6국03-03] | F9: 체험한 일에 대한 감상을 나타내는 글을 쓴다. | G9: 단일 학년 | H9: 자동 대조
A10: 국어 | B10: 1학기 | C10: 4. 대상을 설명해요 › 2. 대상을 설명하는 글 쓰기 | D10: (3) 쓰기 | E10: [6국03-05] | F10: 쓰기 과정을 점검⋅조정하며 글을 쓰고, 글 전체를 대상으로 통일성 있게 고쳐 쓴다. | G10: 두 학년 공통 | H10: 자동 대조
A11: 국어 | B11: 1학기 | C11: 6. 작품을 즐겨요 › 1. 비유적 표현을 알고 시 낭송하기 | D11: (5) 문학 | E11: [6국05-02] | F11: 비유적 표현의 효과에 유의하여 작품을 감상한다. | G11: 단일 학년 | H11: 자동 대조
A12: 국어 | B12: 1학기 | C12: 3. 발표하고 질문해요 | D12: (6) 매체 | E12: [6국06-01] | F12: 정보 검색 도구를 활용하여 자신의 목적에 맞는 매체 자료를 찾는다. | G12: 단일 학년 | H12: 자동 대조
... A161: 미술 | B161: 2학기 | C161: 13. 미술가의 시간 여행 | D161: (3) 감상 | E161: [6미03-04] | F161: 다양한 방법을 활용하여 작품을 감상하며 작품에 관한 서로 다른 관점을 존중할 수 있다. | G161: 두 학년 반복·심화 | H161: 자동 대조

Sheet 6학년
A1: 교과 | B1: 학기 | C1: 단원 | D1: 영역 | E1: 코드 | F1: 성취기준 | G1: 구분 | H1: 근거
A2: 국어 | B2: 1학기 | C2: 3. 절차를 지키며 토론해요 › 2. 문제를 정하여 토론하기 | D2: (1) 듣기⋅말하기 | E2: [6국01-07] | F2: 절차와 규칙을 지키고 타당한 이유와 근거를 제시하며 토론한다. | G2: 단일 학년 | H2: 자동 대조
A3: 국어 | B3: 1학기 | C3: 6. 비판적으로 읽어요 › 2. 표현의 적절성을 판단하며 읽기 | D3: (2) 읽기 | E3: [6국02-03] | F3: 글이나 자료를 읽고 내용의 타당성과 표현의 적절성을 평가한다. | G3: 단일 학년 | H3: 자동 대조
A4: 국어 | B4: 1학기 | C4: 6. 비판적으로 읽어요 › 2. 표현의 적절성을 판단하며 읽기 | D4: (2) 읽기 | E4: [6국02-05] | F4: 긍정적인 읽기 동기를 형성하고 적극적으로 읽기에 참여하는 태도를 기른다. | G4: 단일 학년 | H4: 자동 대조
A5: 국어 | B5: 1학기 | C5: 5. 자신의 글쓰기 과정을 살펴봐요 | D5: (3) 쓰기 | E5: [6국03-02] | F5: 적절한 근거를 사용하고 인용의 출처를 밝히며 주장하는 글을 쓴다. | G5: 단일 학년 | H5: 자동 대조
A6: 국어 | B6: 1학기 | C6: 2. 바르게 고쳐 써요 | D6: (3) 쓰기 | E6: [6국03-05] | F6: 쓰기 과정을 점검⋅조정하며 글을 쓰고, 글 전체를 대상으로 통일성 있게 고쳐 쓴다. | G6: 두 학년 공통 | H6: 자동 대조
A7: 국어 | B7: 1학기 | C7: 4. 상황에 맞게 표현해요 | D7: (4) 문법 | E7: [6국04-03] | F7: 고유어와 관용 표현의 쓰임과 가치를 이해하고 상황에 맞게 표현한다. | G7: 단일 학년 | H7: 자동 대조
A8: 국어 | B8: 1학기 | C8: 2. 바르게 고쳐 써요 | D8: (4) 문법 | E8: [6국04-04] | F8: 문장 성분을 이해하고 호응 관계가 올바른 문장을 구성한다. | G8: 단일 학년 | H8: 검토 보정
A9: 국어 | B9: 1학기 | C9: 4. 상황에 맞게 표현해요 | D9: (4) 문법 | E9: [6국04-05] | F9: 글과 담화에 쓰인 시간 표현을 이해하고 상황에 맞게 표현한다. | G9: 단일 학년 | H9: 자동 대조
A10: 국어 | B10: 1학기 | C10: 2. 바르게 고쳐 써요 | D10: (4) 문법 | E10: [6국04-06] | F10: 글과 담화에 쓰인 단어 및 문장, 띄어쓰기를 민감하게 살펴 바르게 고치는 태도를 지닌다. | G10: 단일 학년 | H10: 자동 대조
A11: 국어 | B11: 1학기 | C11: 5. 자신의 글쓰기 과정을 살펴봐요 | D11: (5) 문학 | E11: [6국05-05] | F11: 자신의 경험을 시, 소설, 극, 수필 등 적절한 갈래로 표현한다. | G11: 단일 학년 | H11: 자동 대조
A12: 국어 | B12: 1학기 | C12: 1. 자신의 삶과 관련지어 읽어요 | D12: (5) 문학 | E12: [6국05-06] | F12: 작품을 읽고 자신의 삶과 연관 지어 성찰하는 태도를 지닌다. | G12: 단일 학년 | H12: 자동 대조
... A161: 미술 | B161: 2학기 | C161: 10. 지붕 없어도 미술관 | D161: (3) 감상 | E161: [6미03-03] | F161: 공동체의 미술 문화 활동에 관심을 가지고 참여하며 경험을 공유할 수 있다. | G161: 두 학년 반복·심화 | H161: 자동 대조

Sheet 미배치
A1: 학년군 | B1: 교과 | C1: 영역 | D1: 코드 | E1: 성취기준 | F1: 비고
A2: 5~6학년군 | B2: 과학 | C2: (9) 산과 염기 | D2: [6과09-01] | E2: 여러 가지 용액에 지시약을 넣었을 때의 변화를 관찰하여 용액을 산성 용액과 염기성 용액으로 분류할 수 있다. | F2: 2026 계획서에 해당 단원 없음 (교육과정 전환기)
A3: 5~6학년군 | B3: 과학 | C3: (9) 산과 염기 | D3: [6과09-02] | E3: 산성 용액과 염기성 용액의 성질을 관찰하고, 산성 용액과 염기성 용액을 섞을 때 용액의 성질 변화를 실험을 통해 추론할 수 있다. | F3: 2026 계획서에 해당 단원 없음 (교육과정 전환기)
A4: 5~6학년군 | B4: 과학 | C4: (9) 산과 염기 | D4: [6과09-03] | E4: 우리 주변에서 산성 용액과 염기성 용액을 이용하는 예를 찾아서 설명할 수 있다. | F4: 2026 계획서에 해당 단원 없음 (교육과정 전환기)
A5: 5~6학년군 | B5: 과학 | C5: (9) 산과 염기 | D5: [6과09-04] | E5: 산성화로 인한 환경의 피해 사례를 소개하는 자료를 만들고 공유할 수 있다. | F5: 2026 계획서에 해당 단원 없음 (교육과정 전환기)
A6: 5~6학년군 | B6: 과학 | C6: (10) 물체의 운동 | D6: [6과10-01] | E6: 운동하는 물체는 시간에 따라 위치가 변화함을 알고 그 변화를 표현할 수 있다. | F6: 2026 계획서에 해당 단원 없음 (교육과정 전환기)
A7: 5~6학년군 | B7: 과학 | C7: (10) 물체의 운동 | D7: [6과10-02] | E7: 물체의 이동 거리와 걸린 시간을 측정하여 속력을 구하고 빠르기를 비교할 수 있다. | F7: 2026 계획서에 해당 단원 없음 (교육과정 전환기)
A8: 5~6학년군 | B8: 과학 | C8: (10) 물체의 운동 | D8: [6과10-03] | E8: 속력과 관련된 안전 수칙과 안전장치를 조사한 결과를 공유하고 일상생활에서 교통안전을 실천할 수 있다. | F8: 2026 계획서에 해당 단원 없음 (교육과정 전환기)

Sheet 전체(학년군 대비)
A1: 학년군 | B1: 교과 | C1: 영역 | D1: 코드 | E1: 성취기준 | F1: 배치 학년 | G1: 학기·단원 | H1: 구분
A2: 1~2학년군 | B2: 국어 | C2: (1) 듣기⋅말하기 | D2: [2국01-05] | E2: 듣기와 말하기에 관심과 흥미를 가진다. | F2: 1학년 · 2학년 | G2: 1학년 1학기 5. 반갑게 인사해요 2학년 1학기 1. 만나서 반가워요! | H2: 두 학년 공통
A3: 1~2학년군 | B3: 국어 | C3: (2) 읽기 | D3: [2국02-01] | E3: 글자, 단어, 문장, 짧은 글을 정확하게 소리 내어 읽는다. | F3: 1학년 | G3: 1학년 1학기 6. 또박또박 읽어요 1학년 2학기 2. 낱말을 정확하게 읽어요 | H3: 단일 학년
A4: 1~2학년군 | B4: 국어 | C4: (2) 읽기 | D4: [2국02-05] | E4: 읽기에 흥미를 가지고 즐겨 읽는 태도를 지닌다. | F4: 1학년 · 2학년 | G4: 1학년 1학기 6. 또박또박 읽어요 2학년 1학기 4. 분위기를 살려 읽어요 | H4: 두 학년 공통
A5: 1~2학년군 | B5: 국어 | C5: (3) 쓰기 | D5: [2국03-01] | E5: 글자와 단어를 바르게 쓴다. | F5: 1학년 | G5: 1학년 1학기 1. 글자를 만들어요 | H5: 단일 학년
A6: 1~2학년군 | B6: 국어 | C6: (4) 문법 | D6: [2국04-01] | E6: 한글 자모의 이름과 소릿값을 알고 정확하게 발음하고 쓴다. | F6: 1학년 | G6: 1학년 1학기 한글 놀이 1학년 1학기 1. 글자를 만들어요 | H6: 단일 학년
A7: 1~2학년군 | B7: 국어 | C7: (4) 문법 | D7: [2국04-02] | E7: 소리와 표기가 다를 수 있음을 알고 단어를 바르게 읽고 쓴다. | F7: 1학년 | G7: 1학년 1학기 2. 받침이 있는 글자를 읽어요 1학년 2학기 6. 문장을 읽고 써요 | H7: 단일 학년
A8: 1~2학년군 | B8: 국어 | C8: (4) 문법 | D8: [2국04-03] | E8: 문장과 문장 부호를 알맞게 쓰고 한글에 호기심을 가진다. | F8: 1학년 | G8: 1학년 1학기 6. 또박또박 읽어요 | H8: 단일 학년
A9: 1~2학년군 | B9: 수학 | C9: (1) 수와 연산 | D9: [2수01-01] | E9: 수의 필요성을 인식하면서 0과 100까지의 수 개념을 이해하고, 수를 세고 읽고 쓸 수 있다. | F9: 1학년 | G9: 1학년 1학기 1. 9까지의 수 1학년 1학기 5. 50까지의 수 1학년 2학기 1. 100까지의 수 | H9: 단일 학년
A10: 1~2학년군 | B10: 수학 | C10: (1) 수와 연산 | D10: [2수01-04] | E10: 하나의 수를 두 수로 분해하고 두 수를 하나의 수로 합성하는 활동을 통하여 수 감각을 기른다. | F10: 1학년 | G10: 1학년 1학기 3. 덧셈과 뺄셈 | H10: 단일 학년
A11: 1~2학년군 | B11: 수학 | C11: (1) 수와 연산 | D11: [2수01-05] | E11: 덧셈과 뺄셈이 이루어지는 실생활 상황과 연결하여 덧셈과 뺄셈의 의미를 이해한다. | F11: 1학년 | G11: 1학년 1학기 3. 덧셈과 뺄셈 | H11: 단일 학년
A12: 1~2학년군 | B12: 수학 | C12: (1) 수와 연산 | D12: [2수01-07] | E12: 덧셈과 뺄셈의 관계를 이해한다. | F12: 1학년 · 2학년 | G12: 1학년 1학기 3. 덧셈과 뺄셈 2학년 1학기 3. 덧셈과 뺄셈 | H12: 두 학년 공통
... A524: 5~6학년군 | B524: 과학 | C524: (10) 물체의 운동 | D524: [6과10-03] | E524: 속력과 관련된 안전 수칙과 안전장치를 조사한 결과를 공유하고 일상생활에서 교통안전을 실천할 수 있다. | F524: - | G524: 미배치 | H524: 2026 계획서에 해당 단원 없음 (교육과정 전환기)
